Traceback (most recent call last):
  File "/Users/andrewbowen/opt/anaconda3/lib/python3.9/site-packages/jupyter_cache/executors/utils.py", line 58, in single_nb_execution
    executenb(
  File "/Users/andrewbowen/opt/anaconda3/lib/python3.9/site-packages/nbclient/client.py", line 1112, in execute
    return NotebookClient(nb=nb, resources=resources, km=km, **kwargs).execute()
  File "/Users/andrewbowen/opt/anaconda3/lib/python3.9/site-packages/nbclient/util.py", line 74, in wrapped
    return just_run(coro(*args, **kwargs))
  File "/Users/andrewbowen/opt/anaconda3/lib/python3.9/site-packages/nbclient/util.py", line 53, in just_run
    return loop.run_until_complete(coro)
  File "/Users/andrewbowen/opt/anaconda3/lib/python3.9/asyncio/base_events.py", line 642, in run_until_complete
    return future.result()
  File "/Users/andrewbowen/opt/anaconda3/lib/python3.9/site-packages/nbclient/client.py", line 553, in async_execute
    await self.async_execute_cell(
  File "/Users/andrewbowen/opt/anaconda3/lib/python3.9/site-packages/nbclient/client.py", line 857, in async_execute_cell
    self._check_raise_for_error(cell, exec_reply)
  File "/Users/andrewbowen/opt/anaconda3/lib/python3.9/site-packages/nbclient/client.py", line 760, in _check_raise_for_error
    raise CellExecutionError.from_cell_and_msg(cell, exec_reply_content)
nbclient.exceptions.CellExecutionError: An error occurred while executing the following cell:
------------------
# Initial read in, converting to parquet format for easier storage
# Uncomment the block below and move the excel file linked into your local data folder

# food_locs = pd.read_excel("data/FoodAccessResearchAtlasData2019.xlsx", sheet_name="Food Access Research Atlas")
food_locs.to_parquet("./data/food_access.parquet", index=False)
# food_locs.head()
------------------

[0;31m---------------------------------------------------------------------------[0m
[0;31mNameError[0m                                 Traceback (most recent call last)
[0;32m/var/folders/60/nwdftyjj6cg3ysz_pf9stwtc0000gn/T/ipykernel_38982/3650492379.py[0m in [0;36m<module>[0;34m[0m
[1;32m      3[0m [0;34m[0m[0m
[1;32m      4[0m [0;31m# food_locs = pd.read_excel("data/FoodAccessResearchAtlasData2019.xlsx", sheet_name="Food Access Research Atlas")[0m[0;34m[0m[0;34m[0m[0m
[0;32m----> 5[0;31m [0mfood_locs[0m[0;34m.[0m[0mto_parquet[0m[0;34m([0m[0;34m"./data/food_access.parquet"[0m[0;34m,[0m [0mindex[0m[0;34m=[0m[0;32mFalse[0m[0;34m)[0m[0;34m[0m[0;34m[0m[0m
[0m[1;32m      6[0m [0;31m# food_locs.head()[0m[0;34m[0m[0;34m[0m[0m

[0;31mNameError[0m: name 'food_locs' is not defined
NameError: name 'food_locs' is not defined

